Workbook

Sheet Transaction
A1: TransactionID | B1: TransactionDate_Clean | C1: CustomerID_Check | D1: ProductID | E1: ProductID_Clean | F1: Region_Clean | G1: RegionClean_ | H1: BusinessUnit_Clean | I1: SalesChannelClean | J1: Quantity | K1: UnitPrice_Clean | L1: ListPrice | M1: GrossRevenue_Analytical | N1: DiscountAmount_Analytical | O1: NetRevenue_Analytical | P1: Currency | Q1: ContractType_Clean | R1: CustomerSegment | S1: ProductCategory | T1: CustumerType | U1: Column1
A2: TXN-10001 | B2: 45674 | C2: C-1006 | D2: =UPPER(Table1[[#This Row],[ProductID_Clean]]) -> P-SI-004 | E2: P-SI-004 | F2: N. AMERICA | G2: =TRIM(Table1[[#This Row],[Region_Clean]]) -> N. AMERICA | H2: Sensors & Instruments | I2: Direct | J2: 3 | K2: 2165.11 | L2: 2450 | M2: 7350 | N2: 854.67 | O2: 6495.33 | P2: USD | Q2: Frame Agreement | R2: Aerospace & Defense | S2: =TRIM(PROPER(_xlfn.XLOOKUP(Table1[[#This Row],[ProductID_Clean]],Table3[ProductID],Table3[Category],"Missing Value",0))) -> Instruments | T2: =_xlfn.XLOOKUP(Table1[[#This Row],[CustomerID_Check]],Table2[CustomerID],Table2[CustomerType],"Missing Value",0) -> Standard
A3: TXN-10002 | B3: 45762 | C3: C-1095 | D3: =UPPER(Table1[[#This Row],[ProductID_Clean]]) -> P-SI-002 | E3: P-SI-002 | F3: LATIN AMERICA | G3: =TRIM(Table1[[#This Row],[Region_Clean]]) -> LATIN AMERICA | H3: Sensors & Instruments | I3: Partner Portal | J3: 2 | K3: 601.3 | L3: 725 | M3: 1450 | N3: 247.4 | O3: 1202.6 | P3: USD | Q3: Standard PO | R3: Manufacturing | S3: =TRIM(PROPER(_xlfn.XLOOKUP(Table1[[#This Row],[ProductID_Clean]],Table3[ProductID],Table3[Category],"Missing Value",0))) -> Sensors | T3: =_xlfn.XLOOKUP(Table1[[#This Row],[CustomerID_Check]],Table2[CustomerID],Table2[CustomerType],"Missing Value",0) -> Strategic
A4: TXN-10003 | B4: 45796 | C4: C-1151 | D4: =UPPER(Table1[[#This Row],[ProductID_Clean]]) -> P-SI-003 | E4: P-SI-003 | F4: LATIN AMERICA | G4: =TRIM(Table1[[#This Row],[Region_Clean]]) -> LATIN AMERICA | H4: Sensors & Instruments | I4: Missing Value | J4: 1 | K4: 1649.98 | L4: 1890 | M4: 1890 | N4: 240.02 | O4: 1649.98 | P4: USD | Q4: Frame Agreement | R4: Manufacturing | S4: =TRIM(PROPER(_xlfn.XLOOKUP(Table1[[#This Row],[ProductID_Clean]],Table3[ProductID],Table3[Category],"Missing Value",0))) -> Instruments | T4: =_xlfn.XLOOKUP(Table1[[#This Row],[CustomerID_Check]],Table2[CustomerID],Table2[CustomerType],"Missing Value",0) -> Standard
A5: TXN-10004 | B5: 45764 | C5: C-1168 | D5: =UPPER(Table1[[#This Row],[ProductID_Clean]]) -> P-SI-006 | E5: P-SI-006 | F5: LATIN AMERICA | G5: =TRIM(Table1[[#This Row],[Region_Clean]]) -> LATIN AMERICA | H5: Sensors & Instruments | I5: Direct | J5: 2 | K5: 168.38 | L5: 215 | M5: 430 | N5: 93.24 | O5: 336.76 | P5: USD | Q5: Frame Agreement | R5: Energy & Utilities | S5: =TRIM(PROPER(_xlfn.XLOOKUP(Table1[[#This Row],[ProductID_Clean]],Table3[ProductID],Table3[Category],"Missing Value",0))) -> Sensors | T5: =_xlfn.XLOOKUP(Table1[[#This Row],[CustomerID_Check]],Table2[CustomerID],Table2[CustomerType],"Missing Value",0) -> Standard
A6: TXN-10005 | B6: 45710 | C6: C-1070 | D6: =UPPER(Table1[[#This Row],[ProductID_Clean]]) -> P-SI-004 | E6: P-SI-004 | F6: EMEA | G6: =TRIM(Table1[[#This Row],[Region_Clean]]) -> EMEA | H6: Sensors & Instruments | I6: Direct | J6: 2 | K6: 2012.7 | L6: 2450 | M6: 4900 | N6: 874.6 | O6: 4025.4 | P6: USD | Q6: Standard PO | R6: Process Industries | S6: =TRIM(PROPER(_xlfn.XLOOKUP(Table1[[#This Row],[ProductID_Clean]],Table3[ProductID],Table3[Category],"Missing Value",0))) -> Instruments | T6: =_xlfn.XLOOKUP(Table1[[#This Row],[CustomerID_Check]],Table2[CustomerID],Table2[CustomerType],"Missing Value",0) -> Strategic
A7: TXN-10006 | B7: 45757 | C7: C-1172 | D7: =UPPER(Table1[[#This Row],[ProductID_Clean]]) -> P-SA-003 | E7: P-SA-003 | F7: N. AMERICA | G7: =TRIM(Table1[[#This Row],[Region_Clean]]) -> N. AMERICA | H7: Software & Analytics | I7: Direct | J7: 1 | K7: 2753.57 | L7: 2750 | M7: 2750 | N7: -3.57 | O7: 2753.57 | P7: USD | Q7: Annual License | R7: Manufacturing | S7: =TRIM(PROPER(_xlfn.XLOOKUP(Table1[[#This Row],[ProductID_Clean]],Table3[ProductID],Table3[Category],"Missing Value",0))) -> Software | T7: =_xlfn.XLOOKUP(Table1[[#This Row],[CustomerID_Check]],Table2[CustomerID],Table2[CustomerType],"Missing Value",0) -> Standard
A8: TXN-10007 | B8: 45836 | C8: C-1108 | D8: =UPPER(Table1[[#This Row],[ProductID_Clean]]) -> P-SI-005 | E8: P-SI-005 | F8: APAC | G8: =TRIM(Table1[[#This Row],[Region_Clean]]) -> APAC | H8: Sensors & Instruments | I8: Direct | J8: 5 | K8: 980.55 | L8: 1120 | M8: 5600 | N8: 697.25 | O8: 4902.75 | P8: USD | Q8: Frame Agreement | R8: Research & Labs | S8: =TRIM(PROPER(_xlfn.XLOOKUP(Table1[[#This Row],[ProductID_Clean]],Table3[ProductID],Table3[Category],"Missing Value",0))) -> Sensors | T8: =_xlfn.XLOOKUP(Table1[[#This Row],[CustomerID_Check]],Table2[CustomerID],Table2[CustomerType],"Missing Value",0) -> Key Account
A9: TXN-10008 | B9: 45755 | C9: C-1045 | D9: =UPPER(Table1[[#This Row],[ProductID_Clean]]) -> P-SA-005 | E9: P-SA-005 | F9: EMEA | G9: =TRIM(Table1[[#This Row],[Region_Clean]]) -> EMEA | H9: Software & Analytics | I9: Direct | J9: 1 | K9: 2642.28 | L9: 3200 | M9: 3200 | N9: 557.72 | O9: 2642.28 | P9: USD | Q9: Annual License | R9: Process Industries | S9: =TRIM(PROPER(_xlfn.XLOOKUP(Table1[[#This Row],[ProductID_Clean]],Table3[ProductID],Table3[Category],"Missing Value",0))) -> Software / Integration | T9: =_xlfn.XLOOKUP(Table1[[#This Row],[CustomerID_Check]],Table2[CustomerID],Table2[CustomerType],"Missing Value",0) -> Strategic
A10: TXN-10009 | B10: 45659 | C10: C-1169 | D10: =UPPER(Table1[[#This Row],[ProductID_Clean]]) -> P-SI-002 | E10: P-SI-002 | F10: EMEA | G10: =TRIM(Table1[[#This Row],[Region_Clean]]) -> EMEA | H10: Sensors & Instruments | I10: Direct | J10: 12 | K10: 657.51 | L10: 725 | M10: 8700 | N10: 809.88 | O10: 7890.12 | P10: USD | Q10: Spot | R10: Manufacturing | S10: =TRIM(PROPER(_xlfn.XLOOKUP(Table1[[#This Row],[ProductID_Clean]],Table3[ProductID],Table3[Category],"Missing Value",0))) -> Sensors | T10: =_xlfn.XLOOKUP(Table1[[#This Row],[CustomerID_Check]],Table2[CustomerID],Table2[CustomerType],"Missing Value",0) -> Key Account
A11: TXN-10010 | B11: 45734 | C11: C-1145 | D11: =UPPER(Table1[[#This Row],[ProductID_Clean]]) -> P-SA-001 | E11: P-SA-001 | F11: N. AMERICA | G11: =TRIM(Table1[[#This Row],[Region_Clean]]) -> N. AMERICA | H11: Software & Analytics | I11: Direct | J11: 1 | K11: 3363.25 | L11: 4200 | M11: 4200 | N11: 836.75 | O11: 3363.25 | P11: USD | Q11: Annual License | R11: Research & Labs | S11: =TRIM(PROPER(_xlfn.XLOOKUP(Table1[[#This Row],[ProductID_Clean]],Table3[ProductID],Table3[Category],"Missing Value",0))) -> Software | T11: =_xlfn.XLOOKUP(Table1[[#This Row],[CustomerID_Check]],Table2[CustomerID],Table2[CustomerType],"Missing Value",0) -> Strategic
A12: TXN-10011 | B12: 45765 | C12: C-1174 | D12: =UPPER(Table1[[#This Row],[ProductID_Clean]]) -> P-SI-001 | E12: P-SI-001 | F12: N. AMERICA | G12: =TRIM(Table1[[#This Row],[Region_Clean]]) -> N. AMERICA | H12: Sensors & Instruments | I12: Direct | J12: 4 | K12: 417.01 | L12: 485 | M12: 1940 | N12: 271.96 | O12: 1668.04 | P12: USD | Q12: Spot | R12: Process Industries | S12: =TRIM(PROPER(_xlfn.XLOOKUP(Table1[[#This Row],[ProductID_Clean]],Table3[ProductID],Table3[Category],"Missing Value",0))) -> Sensors | T12: =_xlfn.XLOOKUP(Table1[[#This Row],[CustomerID_Check]],Table2[CustomerID],Table2[CustomerType],"Missing Value",0) -> Key Account
A13: TXN-10012 | B13: 45797 | C13: C-1126 | D13: =UPPER(Table1[[#This Row],[ProductID_Clean]]) -> P-SI-004 | E13: P-SI-004 | F13: EMEA | G13: =TRIM(Table1[[#This Row],[Region_Clean]]) -> EMEA | H13: Sensors & Instruments | I13: Partner Portal | J13: 10 | K13: 2036.06 | L13: 2450 | M13: 24500 | N13: 4139.4 | O13: 20360.6 | P13: USD | Q13: Frame Agreement | R13: Energy & Utilities | S13: =TRIM(PROPER(_xlfn.XLOOKUP(Table1[[#This Row],[ProductID_Clean]],Table3[ProductID],Table3[Category],"Missing Value",0))) -> Instruments | T13: =_xlfn.XLOOKUP(Table1[[#This Row],[CustomerID_Check]],Table2[CustomerID],Table2[CustomerType],"Missing Value",0) -> Standard
... A1218: TXN-11292 | B1218: 45766 | C1218: C-1102 | D1218: =UPPER(Table1[[#This Row],[ProductID_Clean]]) -> P-FS-001 | E1218: P-FS-001 | F1218: LATIN AMERICA | G1218: =TRIM(Table1[[#This Row],[Region_Clean]]) -> LATIN AMERICA | H1218: Field Services | I1218: Distributor | J1218: 1 | K1218: 1333.75 | L1218: 1850 | M1218: 1850 | N1218: 516.25 | O1218: 1333.75 | P1218: USD | Q1218: Standard PO | R1218: Manufacturing | S1218: =TRIM(PROPER(_xlfn.XLOOKUP(Table1[[#This Row],[ProductID_Clean]],Table3[ProductID],Table3[Category],"Missing Value",0))) -> Services | T1218: =_xlfn.XLOOKUP(Table1[[#This Row],[CustomerID_Check]],Table2[CustomerID],Table2[CustomerType],"Missing Value",0) -> Emerging
A1219: Total | J1219: =SUBTOTAL(109,Table1[Quantity]) -> 3470 | M1219: =SUBTOTAL(109,Table1[GrossRevenue_Analytical]) -> 4586720 | N1219: =SUBTOTAL(109,Table1[DiscountAmount_Analytical]) -> 672959.56 | O1219: =SUBTOTAL(109,Table1[NetRevenue_Analytical]) -> 3913760.4
M1221: Discount Rate | N1221: =Table1[[#Totals],[DiscountAmount_Analytical]]/Table1[[#Totals],[GrossRevenue_Analytical]] -> 0.14671913
O1222: Business Unit | P1222: Gross Revenue | Q1222: Discount | R1222: Discount Rate (%) | S1222: Net Revenue | T1222: Revenue Contribution (%) | U1222: Quantity
O1223: Sensors & Instruments | P1223: =SUMIF(Table1[BusinessUnit_Clean],Table8[[#This Row],[Business Unit]],Table1[GrossRevenue_Analytical]) -> 2647045 | Q1223: =SUMIF(Table1[BusinessUnit_Clean],Table8[[#This Row],[Business Unit]],Table1[DiscountAmount_Analytical]) -> 387131.82 | R1223: =Table8[[#This Row],[Discount]]/Table8[[#This Row],[Gross Revenue]] -> 0.14625056 | S1223: =SUMIF(Table1[BusinessUnit_Clean],Table8[[#This Row],[Business Unit]],Table1[NetRevenue_Analytical]) -> 2259913.2 | T1223: =Table8[[#This Row],[Net Revenue]]/Table8[[#Totals],[Net Revenue]] -> 0.57532475 | U1223: =SUMIF(Table1[BusinessUnit_Clean],Table8[[#This Row],[Business Unit]],Table1[Quantity]) -> 2922
O1224: Software & Analytics | P1224: =SUMIF(Table1[BusinessUnit_Clean],Table8[[#This Row],[Business Unit]],Table1[GrossRevenue_Analytical]) -> 1511650 | Q1224: =SUMIF(Table1[BusinessUnit_Clean],Table8[[#This Row],[Business Unit]],Table1[DiscountAmount_Analytical]) -> 216870.24 | R1224: =Table8[[#This Row],[Discount]]/Table8[[#This Row],[Gross Revenue]] -> 0.14346591 | S1224: =SUMIF(Table1[BusinessUnit_Clean],Table8[[#This Row],[Business Unit]],Table1[NetRevenue_Analytical]) -> 1294779.8 | T1224: =Table8[[#This Row],[Net Revenue]]/Table8[[#Totals],[Net Revenue]] -> 0.32962277 | U1224: =SUMIF(Table1[BusinessUnit_Clean],Table8[[#This Row],[Business Unit]],Table1[Quantity]) -> 357
O1225: Field Services | P1225: =SUMIF(Table1[BusinessUnit_Clean],Table8[[#This Row],[Business Unit]],Table1[GrossRevenue_Analytical]) -> 444000 | Q1225: =SUMIF(Table1[BusinessUnit_Clean],Table8[[#This Row],[Business Unit]],Table1[DiscountAmount_Analytical]) -> 70627.65 | R1225: =Table8[[#This Row],[Discount]]/Table8[[#This Row],[Gross Revenue]] -> 0.15907128 | S1225: =SUMIF(Table1[BusinessUnit_Clean],Table8[[#This Row],[Business Unit]],Table1[NetRevenue_Analytical]) -> 373372.35 | T1225: =Table8[[#This Row],[Net Revenue]]/Table8[[#Totals],[Net Revenue]] -> 0.095052481 | U1225: =SUMIF(Table1[BusinessUnit_Clean],Table8[[#This Row],[Business Unit]],Table1[Quantity]) -> 204
O1226: Total | P1226: =SUBTOTAL(109,Table8[Gross Revenue]) -> 4602695 | Q1226: =SUBTOTAL(109,Table8[Discount]) -> 674629.71 | S1226: =SUBTOTAL(109,Table8[Net Revenue]) -> 3928065.3 | T1226: =SUBTOTAL(109,Table8[Revenue Contribution (%)]) -> 1 | U1226: =SUBTOTAL(109,Table8[Quantity]) -> 3483
O1228: Business Unit | P1228: Gross Revenue | Q1228: Discount | R1228: Net Revenue | S1228: Net Revenue Contribution % | T1228: Quantity
O1229: Field Services | P1229: 442550 | Q1229: 70491.39 | R1229: =Business_Unit_Valid_Product_Revenue[[#This Row],[Gross Revenue]]-Business_Unit_Valid_Product_Revenue[[#This Row],[Discount]] -> 372058.61 | S1229: =Business_Unit_Valid_Product_Revenue[[#This Row],[Net Revenue]]/Business_Unit_Valid_Product_Revenue[[#Totals],[Net Revenue]] -> 0.095064227 | T1229: 203
O1230: Software & Analytics | P1230: 1505150 | Q1230: 216197.72 | R1230: =Business_Unit_Valid_Product_Revenue[[#This Row],[Gross Revenue]]-Business_Unit_Valid_Product_Revenue[[#This Row],[Discount]] -> 1288952.3 | S1230: =Business_Unit_Valid_Product_Revenue[[#This Row],[Net Revenue]]/Business_Unit_Valid_Product_Revenue[[#Totals],[Net Revenue]] -> 0.32933857 | T1230: 354
O1231: Sensors & Instruments | P1231: 2639020 | Q1231: 386270.45 | R1231: =Business_Unit_Valid_Product_Revenue[[#This Row],[Gross Revenue]]-Business_Unit_Valid_Product_Revenue[[#This Row],[Discount]] -> 2252749.5 | S1231: =Business_Unit_Valid_Product_Revenue[[#This Row],[Net Revenue]]/Business_Unit_Valid_Product_Revenue[[#Totals],[Net Revenue]] -> 0.5755972 | T1231: 2913
O1232: Total | P1232: =SUBTOTAL(109,Business_Unit_Valid_Product_Revenue[Gross Revenue]) -> 4586720 | R1232: =SUBTOTAL(109,Business_Unit_Valid_Product_Revenue[Net Revenue]) -> 3913760.4 | S1232: =SUBTOTAL(109,Business_Unit_Valid_Product_Revenue[Net Revenue Contribution %]) -> 1 | T1232: =SUBTOTAL(109,Business_Unit_Valid_Product_Revenue[Quantity]) -> 3470
O1235: Region | P1235: Gross Revenue | Q1235: Discount | R1235: Discount Rate (%) | S1235: Net Revenue | T1235: Revenue Contribution (%) | U1235: Quantity
O1236: N. AMERICA | P1236: =SUMIF(Table1[RegionClean_],Table9[[#This Row],[Region]],Table1[GrossRevenue_Analytical]) -> 1804200 | Q1236: =SUMIF(Table1[RegionClean_],Table9[[#This Row],[Region]],Table1[DiscountAmount_Analytical]) -> 243296.87 | R1236: =Table9[[#This Row],[Discount]]/Table9[[#This Row],[Gross Revenue]] -> 0.13485028 | S1236: =SUMIF(Table1[RegionClean_],Table9[[#This Row],[Region]],Table1[NetRevenue_Analytical]) -> 1560903.1 | T1236: =Table9[[#This Row],[Net Revenue]]/Table9[[#Totals],[Net Revenue]] -> 0.39737199 | U1236: =SUMIF(Table1[RegionClean_],Table9[[#This Row],[Region]],Table1[Quantity]) -> 1394
O1237: EMEA | P1237: =SUMIF(Table1[RegionClean_],Table9[[#This Row],[Region]],Table1[GrossRevenue_Analytical]) -> 1484225 | Q1237: =SUMIF(Table1[RegionClean_],Table9[[#This Row],[Region]],Table1[DiscountAmount_Analytical]) -> 197909.43 | R1237: =Table9[[#This Row],[Discount]]/Table9[[#This Row],[Gross Revenue]] -> 0.13334193 | S1237: =SUMIF(Table1[RegionClean_],Table9[[#This Row],[Region]],Table1[NetRevenue_Analytical]) -> 1286315.6 | T1237: =Table9[[#This Row],[Net Revenue]]/Table9[[#Totals],[Net Revenue]] -> 0.32746797 | U1237: =SUMIF(Table1[RegionClean_],Table9[[#This Row],[Region]],Table1[Quantity]) -> 1116
F1238: Month | G1238: Gross Revenue | H1238: Discount | I1238: Net Revenue | J1238: Revenue Growth (%) | K1238: Quantity | O1238: APAC | P1238: =SUMIF(Table1[RegionClean_],Table9[[#This Row],[Region]],Table1[GrossRevenue_Analytical]) -> 814715 | Q1238: =SUMIF(Table1[RegionClean_],Table9[[#This Row],[Region]],Table1[DiscountAmount_Analytical]) -> 148525.88 | R1238: =Table9[[#This Row],[Discount]]/Table9[[#This Row],[Gross Revenue]] -> 0.18230409 | S1238: =SUMIF(Table1[RegionClean_],Table9[[#This Row],[Region]],Table1[NetRevenue_Analytical]) -> 666189.12 | T1238: =Table9[[#This Row],[Net Revenue]]/Table9[[#Totals],[Net Revenue]] -> 0.16959726 | U1238: =SUMIF(Table1[RegionClean_],Table9[[#This Row],[Region]],Table1[Quantity]) -> 617
F1239: 45688 | G1239: =SUMIFS(Table1[GrossRevenue_Analytical],Table1[TransactionDate_Clean],">"&EOMONTH(Table12[[#This Row],[Month]],-1),Table1[TransactionDate_Clean],"<="&Table12[[#This Row],[Month]]) -> 644255 | H1239: =SUMIFS(Table1[DiscountAmount_Analytical],Table1[TransactionDate_Clean],">"&EOMONTH(Table12[[#This Row],[Month]],-1),Table1[TransactionDate_Clean],"<="&Table12[[#This Row],[Month]]) -> 101513.06 | I1239: =SUMIFS(Table1[NetRevenue_Analytical],Table1[TransactionDate_Clean],">"&EOMONTH(Table12[[#This Row],[Month]],-1),Table1[TransactionDate_Clean],"<="&Table12[[#This Row],[Month]]) -> 542741.94 | J1239: — | K1239: =SUMIFS(Table1[Quantity],Table1[TransactionDate_Clean],">"&EOMONTH(Table12[[#This Row],[Month]],-1),Table1[TransactionDate_Clean],"<="&Table12[[#This Row],[Month]]) -> 496 | O1239: LATIN AMERICA | P1239: =SUMIF(Table1[RegionClean_],Table9[[#This Row],[Region]],Table1[GrossRevenue_Analytical]) -> 499555 | Q1239: =SUMIF(Table1[RegionClean_],Table9[[#This Row],[Region]],Table1[DiscountAmount_Analytical]) -> 84897.53 | R1239: =Table9[[#This Row],[Discount]]/Table9[[#This Row],[Gross Revenue]] -> 0.16994631 | S1239: =SUMIF(Table1[RegionClean_],Table9[[#This Row],[Region]],Table1[NetRevenue_Analytical]) -> 414657.47 | T1239: =Table9[[#This Row],[Net Revenue]]/Table9[[#Totals],[Net Revenue]] -> 0.10556277 | U1239: =SUMIF(Table1[RegionClean_],Table9[[#This Row],[Region]],Table1[Quantity]) -> 356
F1240: 45716 | G1240: =SUMIFS(Table1[GrossRevenue_Analytical],Table1[TransactionDate_Clean],">"&EOMONTH(Table12[[#This Row],[Month]],-1),Table1[TransactionDate_Clean],"<="&Table12[[#This Row],[Month]]) -> 562320 | H1240: =SUMIFS(Table1[DiscountAmount_Analytical],Table1[TransactionDate_Clean],">"&EOMONTH(Table12[[#This Row],[Month]],-1),Table1[TransactionDate_Clean],"<="&Table12[[#This Row],[Month]]) -> 84533 | I1240: =SUMIFS(Table1[NetRevenue_Analytical],Table1[TransactionDate_Clean],">"&EOMONTH(Table12[[#This Row],[Month]],-1),Table1[TransactionDate_Clean],"<="&Table12[[#This Row],[Month]]) -> 477787 | J1240: =(Table12[[#This Row],[Net Revenue]]-I1239)/I1239 -> -0.11967923 | K1240: =SUMIFS(Table1[Quantity],Table1[TransactionDate_Clean],">"&EOMONTH(Table12[[#This Row],[Month]],-1),Table1[TransactionDate_Clean],"<="&Table12[[#This Row],[Month]]) -> 499 | O1240: Total | P1240: =SUBTOTAL(109,Table9[Gross Revenue]) -> 4602695 | Q1240: =SUBTOTAL(109,Table9[Discount]) -> 674629.71 | S1240: =SUBTOTAL(109,Table9[Net Revenue]) -> 3928065.3 | T1240: =SUBTOTAL(109,Table9[Revenue Contribution (%)]) -> 1 | U1240: =SUBTOTAL(109,Table9[Quantity]) -> 3483
F1241: 45747 | G1241: =SUMIFS(Table1[GrossRevenue_Analytical],Table1[TransactionDate_Clean],">"&EOMONTH(Table12[[#This Row],[Month]],-1),Table1[TransactionDate_Clean],"<="&Table12[[#This Row],[Month]]) -> 688795 | H1241: =SUMIFS(Table1[DiscountAmount_Analytical],Table1[TransactionDate_Clean],">"&EOMONTH(Table12[[#This Row],[Month]],-1),Table1[TransactionDate_Clean],"<="&Table12[[#This Row],[Month]]) -> 94640.99 | I1241: =SUMIFS(Table1[NetRevenue_Analytical],Table1[TransactionDate_Clean],">"&EOMONTH(Table12[[#This Row],[Month]],-1),Table1[TransactionDate_Clean],"<="&Table12[[#This Row],[Month]]) -> 594154.01 | J1241: =(Table12[[#This Row],[Net Revenue]]-I1240)/I1240 -> 0.24355416 | K1241: =SUMIFS(Table1[Quantity],Table1[TransactionDate_Clean],">"&EOMONTH(Table12[[#This Row],[Month]],-1),Table1[TransactionDate_Clean],"<="&Table12[[#This Row],[Month]]) -> 581
F1242: 45777 | G1242: =SUMIFS(Table1[GrossRevenue_Analytical],Table1[TransactionDate_Clean],">"&EOMONTH(Table12[[#This Row],[Month]],-1),Table1[TransactionDate_Clean],"<="&Table12[[#This Row],[Month]]) -> 847870 | H1242: =SUMIFS(Table1[DiscountAmount_Analytical],Table1[TransactionDate_Clean],">"&EOMONTH(Table12[[#This Row],[Month]],-1),Table1[TransactionDate_Clean],"<="&Table12[[#This Row],[Month]]) -> 115587.19 | I1242: =SUMIFS(Table1[NetRevenue_Analytical],Table1[TransactionDate_Clean],">"&EOMONTH(Table12[[#This Row],[Month]],-1),Table1[TransactionDate_Clean],"<="&Table12[[#This Row],[Month]]) -> 732282.81 | J1242: =(Table12[[#This Row],[Net Revenue]]-I1241)/I1241 -> 0.23247979 | K1242: =SUMIFS(Table1[Quantity],Table1[TransactionDate_Clean],">"&EOMONTH(Table12[[#This Row],[Month]],-1),Table1[TransactionDate_Clean],"<="&Table12[[#This Row],[Month]]) -> 645 | O1242: Region | P1242: Column1 | Q1242: Gross Revenue | R1242: Discount | S1242: Net Revenue | T1242: Net Contribution | U1242: Quantity
F1243: 45808 | G1243: =SUMIFS(Table1[GrossRevenue_Analytical],Table1[TransactionDate_Clean],">"&EOMONTH(Table12[[#This Row],[Month]],-1),Table1[TransactionDate_Clean],"<="&Table12[[#This Row],[Month]]) -> 882260 | H1243: =SUMIFS(Table1[DiscountAmount_Analytical],Table1[TransactionDate_Clean],">"&EOMONTH(Table12[[#This Row],[Month]],-1),Table1[TransactionDate_Clean],"<="&Table12[[#This Row],[Month]]) -> 132063.05 | I1243: =SUMIFS(Table1[NetRevenue_Analytical],Table1[TransactionDate_Clean],">"&EOMONTH(Table12[[#This Row],[Month]],-1),Table1[TransactionDate_Clean],"<="&Table12[[#This Row],[Month]]) -> 750196.95 | J1243: =(Table12[[#This Row],[Net Revenue]]-I1242)/I1242 -> 0.024463417 | K1243: =SUMIFS(Table1[Quantity],Table1[TransactionDate_Clean],">"&EOMONTH(Table12[[#This Row],[Month]],-1),Table1[TransactionDate_Clean],"<="&Table12[[#This Row],[Month]]) -> 590 | O1243: N. AMERICA | Q1243: 1800120 | R1243: 242814.14 | S1243: =Invalid_ProductID_Exclusion[[#This Row],[Gross Revenue]]-Invalid_ProductID_Exclusion[[#This Row],[Discount]] -> 1557305.9 | T1243: =Invalid_ProductID_Exclusion[[#This Row],[Net Revenue]]/Invalid_ProductID_Exclusion[[#Totals],[Net Revenue]] -> 0.39790526 | U1243: 1391
F1244: 45838 | G1244: =SUMIFS(Table1[GrossRevenue_Analytical],Table1[TransactionDate_Clean],">"&EOMONTH(Table12[[#This Row],[Month]],-1),Table1[TransactionDate_Clean],"<="&Table12[[#This Row],[Month]]) -> 977195 | H1244: =SUMIFS(Table1[DiscountAmount_Analytical],Table1[TransactionDate_Clean],">"&EOMONTH(Table12[[#This Row],[Month]],-1),Table1[TransactionDate_Clean],"<="&Table12[[#This Row],[Month]]) -> 146292.42 | I1244: =SUMIFS(Table1[NetRevenue_Analytical],Table1[TransactionDate_Clean],">"&EOMONTH(Table12[[#This Row],[Month]],-1),Table1[TransactionDate_Clean],"<="&Table12[[#This Row],[Month]]) -> 830902.58 | J1244: =(Table12[[#This Row],[Net Revenue]]-I1243)/I1243 -> 0.10757926 | K1244: =SUMIFS(Table1[Quantity],Table1[TransactionDate_Clean],">"&EOMONTH(Table12[[#This Row],[Month]],-1),Table1[TransactionDate_Clean],"<="&Table12[[#This Row],[Month]]) -> 672 | O1244: EMEA | Q1244: 1474750 | R1244: 197046.59 | S1244: =Invalid_ProductID_Exclusion[[#This Row],[Gross Revenue]]-Invalid_ProductID_Exclusion[[#This Row],[Discount]] -> 1277703.4 | T1244: =Invalid_ProductID_Exclusion[[#This Row],[Net Revenue]]/Invalid_ProductID_Exclusion[[#Totals],[Net Revenue]] -> 0.32646439 | U1244: 1110
F1245: Total | G1245: =SUBTOTAL(109,Table12[Gross Revenue]) -> 4602695 | H1245: =SUBTOTAL(109,Table12[Discount]) -> 674629.71 | I1245: =SUBTOTAL(109,Table12[Net Revenue]) -> 3928065.3 | K1245: =SUBTOTAL(109,Table12[Quantity]) -> 3483 | O1245: APAC | Q1245: 812295 | R1245: 148201.3 | S1245: =Invalid_ProductID_Exclusion[[#This Row],[Gross Revenue]]-Invalid_ProductID_Exclusion[[#This Row],[Discount]] -> 664093.7 | T1245: =Invalid_ProductID_Exclusion[[#This Row],[Net Revenue]]/Invalid_ProductID_Exclusion[[#Totals],[Net Revenue]] -> 0.16968174 | U1245: 613
O1246: LATIN AMERICA | Q1246: 499555 | R1246: 84897.53 | S1246: =Invalid_ProductID_Exclusion[[#This Row],[Gross Revenue]]-Invalid_ProductID_Exclusion[[#This Row],[Discount]] -> 414657.47 | T1246: =Invalid_ProductID_Exclusion[[#This Row],[Net Revenue]]/Invalid_ProductID_Exclusion[[#Totals],[Net Revenue]] -> 0.10594861 | U1246: 356
O1247: Total | Q1247: =SUBTOTAL(109,Invalid_ProductID_Exclusion[Gross Revenue]) -> 4586720 | R1247: =SUBTOTAL(109,Invalid_ProductID_Exclusion[Discount]) -> 672959.56 | S1247: =SUBTOTAL(109,Invalid_ProductID_Exclusion[Net Revenue]) -> 3913760.4 | T1247: =SUBTOTAL(109,Invalid_ProductID_Exclusion[Net Contribution]) -> 1 | U1247: =SUBTOTAL(109,Invalid_ProductID_Exclusion[Quantity]) -> 3470
O1249: Product Category | P1249: Gross Revenue | Q1249: Discount | R1249: Discount Rate % | S1249: Net Revenue | T1249: Net Revenue Contribution % | U1249: Quantity
...

Sheet Custumer
A1: CustomerID | B1: CustomerName | C1: CustomerName_Clean | D1: CustomerSegment | E1: CustomerSegment_Clean | F1: CustomerType | G1: Region | H1: Region_Clean | I1: Industry | J1: AccountStatus | K1: AccountStatus_Clean | L1: PrimaryContact | M1: CreditLimit | N1: CreditLimit_Clean
A2: C-1001 | B2: Rodriguez Figueroa and Sanchez | C2: Rodriguez Figueroa And Sanchez | D2: ENERGY & UTILITIES | E2: Energy & Utilities | F2: Standard | G2: Latin America | H2: LATIN AMERICA | I2: Oil & Gas | J2: Active | K2: Active | L2: Brian Yang | M2: 100000 | N2: 100000
A3: C-1002 | B3: Miller Henderson and Johnson | C3: Miller Henderson And Johnson | D3: Manufacturing | E3: Manufacturing | F3: Emerging | G3: North America | H3: N. AMERICA | I3: Discrete Manufacturing | J3: Active | K3: Active | L3: Jonathan Johnson | M3: 500000 | N3: 500000
A4: C-1003 | B4: Baldwin Ltd Corp | C4: Baldwin Ltd Corp | D4: MANUFACTURING | E4: Manufacturing | F4: Emerging | G4: Latin America | H4: LATIN AMERICA | I4: Automotive | J4: Active | K4: Active | L4: Connie Lawrence | M4: 100000 | N4: 100000
A5: C-1004 | B5: Blake and Sons Inc | C5: Blake And Sons Inc | D5: Manufacturing | E5: Manufacturing | F5: Standard | G5: North America | H5: N. AMERICA | I5: Automotive | J5: Active | K5: Active | L5: Gina Moore | M5: 100000 | N5: 100000
A6: C-1005 | B6: Garcia-James LLC | C6: Garcia-James Llc | D6: PROCESS INDUSTRIES | E6: Process Industries | F6: Key Account | G6: North america | H6: N. AMERICA | I6: Chemicals | J6: Active | K6: Active | L6: Gregory Baker | M6: 250000 | N6: 250000
A7: C-1006 | B7: Blair PLC AG | C7: Blair Plc Ag | D7: AEROSPACE & DEFENSE | E7: Aerospace & Defense | F7: Standard | G7: North America | H7: N. AMERICA | I7: Avionics | J7: Active | K7: Active | L7: Thomas Miller | M7: 50000 | N7: 50000
A8: C-1007 | B8: Calderon-Montgomery Co | C8: Calderon-Montgomery Co | D8: Process Industries | E8: Process Industries | F8: Strategic | G8: North America | H8: N. AMERICA | I8: Food & Beverage | J8: Active | K8: Active | L8: Laura Bush | M8: 2500000 | N8: 2500000
A9: C-1008 | B9: Stanley LLC | C9: Stanley Llc | D9: Aerospace & Defense | E9: Aerospace & Defense | F9: Strategic | G9: North America | H9: N. AMERICA | I9: Aerospace OEM | J9: Active | K9: Active | L9: Dr. Sharon James | M9: 250000 | N9: 250000
A10: C-1009 | B10: Reid-Diaz | C10: Reid-Diaz | D10: MANUFACTURING | E10: Manufacturing | F10: Strategic | G10: EMEA | H10: EMEA | I10: Discrete Manufacturing | J10: Active | K10: Active | L10: Daniel Adams | M10: $100,000 | N10: 100000
A11: C-1010 | B11: wong lynch and jackson | C11: Wong Lynch And Jackson | D11: Process Industries | E11: Process Industries | F11: Standard | G11: North America | H11: N. AMERICA | I11: Food & Beverage | J11: Active | K11: Active | L11: Carla Gray | M11: 100000 | N11: 100000
A12: C-1011 | B12: Watts Robinson and Nguyen LLC | C12: Watts Robinson And Nguyen Llc | D12: Research & Labs | E12: Research & Labs | F12: Emerging | G12: APAC | H12: APAC | I12: Private R&D | J12: Active | K12: Active | L12: Amy Underwood | M12: 250000 | N12: 250000
A13: C-1012 | B13: Morales-Jones Pty Ltd | C13: Morales-Jones Pty Ltd | D13: Research & Labs | E13: Research & Labs | F13: Key Account | G13: North america | H13: N. AMERICA | I13: University Lab | J13: Active | K13: Active | L13: Latoya Robbins | M13: 100000 | N13: 100000
A14: C-1013 | B14: Rios Group SA | C14: Rios Group Sa | D14: Energy & Utilities | E14: Energy & Utilities | F14: Emerging | G14: North America | H14: N. AMERICA | I14: Renewables | J14: Active | K14: Active | L14: Maria Thomas | M14: 100000 | N14: 100000
A15: C-1014 | B15: Wright PLC | C15: Wright Plc | D15: Process Industries | E15: Process Industries | F15: Standard | G15: North America | H15: N. AMERICA | I15: Pulp & Paper | J15: Active | K15: Active | L15: Nicole Patterson | M15: 2500000 | N15: 2500000
A16: C-1015 | B16: Ross Robinson and Bright Pty Ltd | C16: Ross Robinson And Bright Pty Ltd | D16: AEROSPACE & DEFENSE | E16: Aerospace & Defense | F16: Strategic | G16: North America | H16: N. AMERICA | I16: Aerospace OEM | J16: Active | K16: Active | L16: Ann Williams | M16: 500000 | N16: 500000
A17: C-1016 | B17: hernandez and sons co | C17: Hernandez And Sons Co | D17: AEROSPACE & DEFENSE | E17: Aerospace & Defense | F17: Strategic | G17: APAC | H17: APAC | I17: MRO | J17: Active | K17: Active | L17: Jennifer Brown | M17: $50,000 | N17: 50000
A18: C-1017 | B18: Carlson-Mcdonald Corporation | C18: Carlson-Mcdonald Corporation | D18: Aerospace & Defense | E18: Aerospace & Defense | F18: Key Account | G18: EMEA | H18: EMEA | I18: Aerospace OEM | J18: Active | K18: Active | L18: Juan Dunlap | M18: 100000 | N18: 100000
A19: C-1018 | B19: Le Maldonado and Herrera | C19: Le Maldonado And Herrera | D19: Energy & Utilities | E19: Energy & Utilities | F19: Standard | G19: APAC | H19: APAC | I19: Renewables | J19: Active | K19: Active | L19: Martin Rodriguez | M19: 250000 | N19: 250000
A20: C-1019 | B20: Moore-Smith | C20: Moore-Smith | D20: Manufacturing | E20: Manufacturing | F20: Standard | G20: APAC | H20: APAC | I20: Discrete Manufacturing | J20: Active | K20: Active | L20: Michelle Stanton | M20: 500000 | N20: 500000
A21: C-1020 | B21: Romero Inc | C21: Romero Inc | D21: Energy & Utilities | E21: Energy & Utilities | F21: Standard | G21: EMEA | H21: EMEA | I21: Utilities | J21: Active | K21: Active | L21: Elizabeth Fowler | M21: 50000 | N21: 50000
A22: C-1021 | B22: Gonzalez Brooks and Martin SA | C22: Gonzalez Brooks And Martin Sa | D22: Manufacturing | E22: Manufacturing | F22: Key Account | G22: EMEA | H22: EMEA | I22: Discrete Manufacturing | J22: Active | K22: Active | L22: Tammy Sellers | M22: 1000000 | N22: 1000000
A23: C-1022 | B23: Nguyen Smith and Hickman LLC | C23: Nguyen Smith And Hickman Llc | D23: Manufacturing | E23: Manufacturing | F23: Standard | G23: North America | H23: N. AMERICA | I23: Machinery | J23: Active | K23: Active | L23: Sandra Parker | M23: 50000 | N23: 50000
A24: C-1023 | B24: Allen PLC | C24: Allen Plc | D24: Manufacturing | E24: Manufacturing | F24: Emerging | G24: North America | H24: N. AMERICA | I24: Automotive | J24: Active | K24: Active | L24: Angelica Tucker | M24: 250000 | N24: 250000
A25: C-1024 | B25: Spence PLC | C25: Spence Plc | D25: Research & Labs | E25: Research & Labs | F25: Key Account | G25: APAC | H25: APAC | I25: National Lab | J25: Active | K25: Active | L25: Betty Alvarez | M25: 250000 | N25: 250000
A26: C-1025 | B26: Martin Rose and Obrien LLC | C26: Martin Rose And Obrien Llc | D26: Aerospace & Defense | E26: Aerospace & Defense | F26: Key Account | G26: Latin America | H26: LATIN AMERICA | I26: Defense Contractor | J26: Active | K26: Active | L26: Tanya Campos | M26: 100000 | N26: 100000
A27: C-1026 | B27: Harris Collins and Carney GmbH | C27: Harris Collins And Carney Gmbh | D27: Energy & Utilities | E27: Energy & Utilities | F27: Emerging | G27: APAC | H27: APAC | I27: Power Generation | J27: Active | K27: Active | L27: Jessica Holmes | M27: 250000 | N27: 250000
A28: C-1027 | B28: Wright Inc | C28: Wright Inc | D28: Energy & Utilities | E28: Energy & Utilities | F28: Strategic | G28: North America | H28: N. AMERICA | I28: Oil & Gas | J28: Active | K28: Active | L28: Kevin Hall | M28: 1000000 | N28: 1000000
A29: C-1028 | B29: Smith Ltd Inc | C29: Smith Ltd Inc | D29: Energy & Utilities | E29: Energy & Utilities | F29: Standard | G29: EMEA | H29: EMEA | I29: Renewables | J29: Active | K29: Active | L29: Crystal Whitehead | M29: 2500000 | N29: 2500000
... A33: C-1032 | B33: Brown Ltd | C33: Brown Ltd | D33: Manufacturing | E33: Manufacturing | F33: Standard | G33: EMEA | H33: EMEA | I33: Electronics | J33: Active | K33: Active | L33: Scott Wright | M33: 500000 | N33: 500000
A34: C-1033 | B34: Herrera and Sons Ltd | C34: Herrera And Sons Ltd | D34: Energy & Utilities | E34: Energy & Utilities | F34: Standard | G34: EMEA | H34: EMEA | I34: Power Generation | J34: Active | K34: Active | L34: Donald Wright | M34: $50,000 | N34: 50000
A35: C-1034 | B35: Ramos PLC | C35: Ramos Plc | D35: Aerospace & Defense | E35: Aerospace & Defense | F35: Key Account | G35: North America | H35: N. AMERICA | I35: MRO | J35: Active | K35: Active | L35: Matthew Fernandez | M35: 250000 | N35: 250000
A36: C-1035 | B36: Novak and Sons | C36: Novak And Sons | D36: Process Industries | E36: Process Industries | F36: Standard | G36: North america | H36: N. AMERICA | I36: Pulp & Paper | J36: Active | K36: Active | L36: John Lewis | M36: 250000 | N36: 250000
A37: C-1036 | B37: Barrera-Martin | C37: Barrera-Martin | D37: Manufacturing | E37: Manufacturing | F37: Standard | G37: EMEA | H37: EMEA | I37: Electronics | J37: Active | K37: Active | L37: James House | M37: 50000 | N37: 50000
A38: C-1037 | B38: Mitchell-Horton Ltd | C38: Mitchell-Horton Ltd | D38: Energy & Utilities | E38: Energy & Utilities | F38: Emerging | G38: North America | H38: N. AMERICA | I38: Utilities | J38: Active | K38: Active | L38: Rachel Stanley | M38: 100000 | N38: 100000
A39: C-1038 | B39: Moore-Phillips Inc | C39: Moore-Phillips Inc | D39: Process Industries | E39: Process Industries | F39: Standard | G39: APAC | H39: APAC | I39: Chemicals | J39: Active | K39: Active | L39: Lauren Daniels | M39: $100,000 | N39: 100000
A40: C-1039 | B40: Edwards Williams and Woods Ltd | C40: Edwards Williams And Woods Ltd | D40: Manufacturing | E40: Manufacturing | F40: Emerging | G40: Latin America | H40: LATIN AMERICA | I40: Electronics | J40: Active | K40: Active | L40: Kim Brown | M40: 100000 | N40: 100000
A41: C-1040 | B41: Miller Lopez and Larson Pty Ltd | C41: Miller Lopez And Larson Pty Ltd | D41: Energy & Utilities | E41: Energy & Utilities | F41: Emerging | G41: APAC | H41: APAC | I41: Utilities | J41: Active | K41: Active | L41: Cynthia Wilson | M41: 500000 | N41: 500000
A42: C-1041 | B42: Sanchez Wheeler and Harvey BV | C42: Sanchez Wheeler And Harvey Bv | D42: Process Industries | E42: Process Industries | F42: Key Account | G42: North america | H42: N. AMERICA | I42: Food & Beverage | J42: Active | K42: Active | L42: Kevin Mills | M42: 250000 | N42: 250000
A43: C-1042 | B43: Harris-Moran | C43: Harris-Moran | D43: MANUFACTURING | E43: Manufacturing | F43: Standard | G43: North America | H43: N. AMERICA | I43: Automotive | J43: Active | K43: Active | L43: James Powers | M43: 100000 | N43: 100000
...

Sheet Product
A1: ProductID | B1: ProductName | C1: ProductName_Clean | D1: Category | E1: Category_Clean | F1: Family | G1: Family_Clean | H1: BU | I1: ListPrice | J1: StdVarCost_Clean | K1: StdFixedAlloc
A2: P-FS-001 | B2: On-Site Commissioning & Calibration | C2: On-Site Commissioning & Calibration | D2: Services | E2: Services | F2: Commissioning | G2: Commissioning | H2: Field Services | I2: 1850 | J2: 980 | K2: 220
A3: P-FS-002 | B3: Annual Maint. Contract - Standard | C3: Annual Maint. Contract - Standard | D3: Services | E3: Services | F3: Maintenance | G3: Maintenance | H3: Field Services | I3: 2400 | J3: 1120 | K3: 280
A4: P-FS-003 | B4: Annual Maintenance Contract - Premium | C4: Annual Maintenance Contract - Premium | D4: Services | E4: Services | F4: Maintenance | G4: Maintenance | H4: Field Services | I4: 4100 | J4: 1850 | K4: 410
A5: P-FS-004 | B5: Emergency Response Call-Out | C5: Emergency Response Call-Out | D5: SERVICES | E5: Services | F5: Emergency | G5: Emergency | H5: Field Services | I5: 3200 | J5: 1650 | K5: 350
A6: P-FS-005 | B6: Training Workshop - Operator Level | C6: Training Workshop - Operator Level | D6: Services | E6: Services | F6: Training | G6: Training | H6: Field Services | I6: 950 | J6: 420 | K6: 95
A7: P-FS-006 | B7: Remote Diagnostics Support (Annual) | C7: Remote Diagnostics Support (Annual) | D7: Services | E7: Services | F7: Support | G7: Support | H7: Field Services | I7: 1450 | J7: 380 | K7: 175
A8: P-SA-001 | B8: AetherView Analytics Plat. - Std | C8: Aetherview Analytics Plat. - Std | D8: Software | E8: Software | F8: Analytics Platform | G8: Analytics Platform | H8: Software & Analytics | I8: 4200 | J8: 185 | K8: 310
A9: P-SA-002 | B9: AetherView Analytics Platform Enterprise | C9: Aetherview Analytics Platform Enterprise | D9: Software | E9: Software | F9: Analytics Platform | G9: Analytics Platform | H9: Software & Analytics | I9: 9800 | J9: 420 | K9: 680
A10: P-SA-003 | B10: ConditionIQ Predictive Module | C10: Conditioniq Predictive Module | D10: Software | E10: Software | F10: Predictive Modules | G10: Predictive Modules | H10: Software & Analytics | I10: 2750 | J10: 95 | K10: 210
A11: P-SA-004 | B11: AssetHealth Dashboard License | C11: Assethealth Dashboard License | D11: Software | E11: Software | F11: Dashboards | G11: Dashboards | H11: Software & Analytics | I11: 1650 | J11: 65 | K11: 145
A12: P-SA-005 | B12: AetherConnect API Integration Pack | C12: Aetherconnect Api Integration Pack | D12: Software / Integration | E12: Software / Integration | F12: Integration | G12: Integration | H12: Software & Analytics | I12: 3200 | J12: 140 | K12: 255
A13: P-SI-001 | B13: AetherProbe XT-200 Temp. Sensor | C13: Aetherprobe Xt-200 Temp. Sensor | D13: SENSORS | E13: Sensors | F13: Temperature | G13: Temperature | H13: Sensors & Instruments | I13: 485 | J13: 187.5 | K13: 42
... A20: P-SI-008 | B20: VibraSense Lite Portable Analyzer | C20: Vibrasense Lite Portable Analyzer | D20: Instruments | E20: Instruments | F20: Vibration | G20: Vibration | H20: Sensors & Instruments | I20: 950 | J20: 385 | K20: 72

Sheet Cost
A1: CostID | B1: Period_Clean | C1: ProductID | D1: ProductID_Clean | E1: CostCategory | F1: CostType | G1: StandardCost | H1: ActualCost_Clean | I1: CostCenter_Clean | J1: Notes | K1: BU
A2: COST-5027 | B2: 2025-01 | C2: P-FS-001 | D2: P-FS-001 | E2: Variable COGS | F2: Variable | G2: 980 | H2: 1126.25 | I2: FS | K2: =_xlfn.XLOOKUP(Table4[[#This Row],[ProductID_Clean]],Table3[ProductID],Table3[BU],"Missing Value",0) -> Field Services | M2: ProductID | N2: Standard Variable Cost | O2: Actual Variable Cost | P2: Cost Variance vs Standard | Q2: Cost Variance vs Standard %
A3: COST-5028 | B3: 2025-01 | C3: P-FS-001 | D3: P-FS-001 | E3: Fixed Allocation | F3: Fixed | G3: 220 | H3: 217.99 | I3: FS | K3: =_xlfn.XLOOKUP(Table4[[#This Row],[ProductID_Clean]],Table3[ProductID],Table3[BU],"Missing Value",0) -> Field Services | M3: P-FS-001 | N3: =_xlfn.XLOOKUP(Table15[[#This Row],[ProductID]],Table3[ProductID],Table3[StdVarCost_Clean]) -> 980 | O3: =_xlfn.XLOOKUP(Table15[[#This Row],[ProductID]],Table4[ProductID_Clean],Table4[ActualCost_Clean]) -> 1126.25 | P3: =Table15[[#This Row],[Standard Variable Cost]]-Table15[[#This Row],[Actual Variable Cost]] -> -146.25 | Q3: =Table15[[#This Row],[Cost Variance vs Standard]]/Table15[[#This Row],[Standard Variable Cost]] -> -0.14923469
A4: COST-5065 | B4: 2025-02 | C4: P-FS-001 | D4: P-FS-001 | E4: Variable COGS | F4: Variable | G4: 980 | H4: 1124.28 | I4: FS | K4: =_xlfn.XLOOKUP(Table4[[#This Row],[ProductID_Clean]],Table3[ProductID],Table3[BU],"Missing Value",0) -> Field Services | M4: P-FS-002 | N4: =_xlfn.XLOOKUP(Table15[[#This Row],[ProductID]],Table3[ProductID],Table3[StdVarCost_Clean]) -> 1120 | O4: =_xlfn.XLOOKUP(Table15[[#This Row],[ProductID]],Table4[ProductID_Clean],Table4[ActualCost_Clean]) -> 1263.71 | P4: =Table15[[#This Row],[Standard Variable Cost]]-Table15[[#This Row],[Actual Variable Cost]] -> -143.71 | Q4: =Table15[[#This Row],[Cost Variance vs Standard]]/Table15[[#This Row],[Standard Variable Cost]] -> -0.1283125
A5: COST-5066 | B5: 2025-02 | C5: P-FS-001 | D5: P-FS-001 | E5: Fixed Allocation | F5: Fixed | G5: 220 | H5: 211.2 | I5: FS | K5: =_xlfn.XLOOKUP(Table4[[#This Row],[ProductID_Clean]],Table3[ProductID],Table3[BU],"Missing Value",0) -> Field Services | M5: P-FS-003 | N5: =_xlfn.XLOOKUP(Table15[[#This Row],[ProductID]],Table3[ProductID],Table3[StdVarCost_Clean]) -> 1850 | O5: =_xlfn.XLOOKUP(Table15[[#This Row],[ProductID]],Table4[ProductID_Clean],Table4[ActualCost_Clean]) -> 2111.06 | P5: =Table15[[#This Row],[Standard Variable Cost]]-Table15[[#This Row],[Actual Variable Cost]] -> -261.06 | Q5: =Table15[[#This Row],[Cost Variance vs Standard]]/Table15[[#This Row],[Standard Variable Cost]] -> -0.14111351
A6: COST-5103 | B6: 2025-03 | C6: P-FS-001 | D6: P-FS-001 | E6: Variable COGS | F6: Variable | G6: 980 | H6: 1108.08 | I6: FS | K6: =_xlfn.XLOOKUP(Table4[[#This Row],[ProductID_Clean]],Table3[ProductID],Table3[BU],"Missing Value",0) -> Field Services | M6: P-FS-004 | N6: =_xlfn.XLOOKUP(Table15[[#This Row],[ProductID]],Table3[ProductID],Table3[StdVarCost_Clean]) -> 1650 | O6: =_xlfn.XLOOKUP(Table15[[#This Row],[ProductID]],Table4[ProductID_Clean],Table4[ActualCost_Clean]) -> 2021.96 | P6: =Table15[[#This Row],[Standard Variable Cost]]-Table15[[#This Row],[Actual Variable Cost]] -> -371.96 | Q6: =Table15[[#This Row],[Cost Variance vs Standard]]/Table15[[#This Row],[Standard Variable Cost]] -> -0.2254303
A7: COST-5104 | B7: 2025-03 | C7: P-FS-001 | D7: P-FS-001 | E7: Fixed Allocation | F7: Fixed | G7: 220 | H7: 224.06 | I7: FS | K7: =_xlfn.XLOOKUP(Table4[[#This Row],[ProductID_Clean]],Table3[ProductID],Table3[BU],"Missing Value",0) -> Field Services | M7: P-FS-005 | N7: =_xlfn.XLOOKUP(Table15[[#This Row],[ProductID]],Table3[ProductID],Table3[StdVarCost_Clean]) -> 420 | O7: =_xlfn.XLOOKUP(Table15[[#This Row],[ProductID]],Table4[ProductID_Clean],Table4[ActualCost_Clean]) -> 408.11 | P7: =Table15[[#This Row],[Standard Variable Cost]]-Table15[[#This Row],[Actual Variable Cost]] -> 11.89 | Q7: =Table15[[#This Row],[Cost Variance vs Standard]]/Table15[[#This Row],[Standard Variable Cost]] -> 0.028309524
A8: COST-5141 | B8: 2025-04 | C8: P-FS-001 | D8: P-FS-001 | E8: Variable COGS | F8: Variable | G8: 980 | H8: 1123.73 | I8: FS | K8: =_xlfn.XLOOKUP(Table4[[#This Row],[ProductID_Clean]],Table3[ProductID],Table3[BU],"Missing Value",0) -> Field Services | M8: P-FS-006 | N8: =_xlfn.XLOOKUP(Table15[[#This Row],[ProductID]],Table3[ProductID],Table3[StdVarCost_Clean]) -> 380 | O8: =_xlfn.XLOOKUP(Table15[[#This Row],[ProductID]],Table4[ProductID_Clean],Table4[ActualCost_Clean]) -> 391.05 | P8: =Table15[[#This Row],[Standard Variable Cost]]-Table15[[#This Row],[Actual Variable Cost]] -> -11.05 | Q8: =Table15[[#This Row],[Cost Variance vs Standard]]/Table15[[#This Row],[Standard Variable Cost]] -> -0.029078947
A9: COST-5142 | B9: 2025-04 | C9: P-FS-001 | D9: P-FS-001 | E9: Fixed Allocation | F9: Fixed | G9: 220 | H9: 220.46 | I9: FS | K9: =_xlfn.XLOOKUP(Table4[[#This Row],[ProductID_Clean]],Table3[ProductID],Table3[BU],"Missing Value",0) -> Field Services | M9: P-SA-001 | N9: =_xlfn.XLOOKUP(Table15[[#This Row],[ProductID]],Table3[ProductID],Table3[StdVarCost_Clean]) -> 185 | O9: =_xlfn.XLOOKUP(Table15[[#This Row],[ProductID]],Table4[ProductID_Clean],Table4[ActualCost_Clean]) -> 200.94 | P9: =Table15[[#This Row],[Standard Variable Cost]]-Table15[[#This Row],[Actual Variable Cost]] -> -15.94 | Q9: =Table15[[#This Row],[Cost Variance vs Standard]]/Table15[[#This Row],[Standard Variable Cost]] -> -0.086162162
A10: COST-5179 | B10: 2025-05 | C10: P-FS-001 | D10: P-FS-001 | E10: Variable COGS | F10: Variable | G10: 980 | H10: 1153.56 | I10: FS | K10: =_xlfn.XLOOKUP(Table4[[#This Row],[ProductID_Clean]],Table3[ProductID],Table3[BU],"Missing Value",0) -> Field Services | M10: P-SA-002 | N10: =_xlfn.XLOOKUP(Table15[[#This Row],[ProductID]],Table3[ProductID],Table3[StdVarCost_Clean]) -> 420 | O10: =_xlfn.XLOOKUP(Table15[[#This Row],[ProductID]],Table4[ProductID_Clean],Table4[ActualCost_Clean]) -> 403.51 | P10: =Table15[[#This Row],[Standard Variable Cost]]-Table15[[#This Row],[Actual Variable Cost]] -> 16.49 | Q10: =Table15[[#This Row],[Cost Variance vs Standard]]/Table15[[#This Row],[Standard Variable Cost]] -> 0.039261905
A11: COST-5180 | B11: 2025-05 | C11: P-FS-001 | D11: P-FS-001 | E11: Fixed Allocation | F11: Fixed | G11: 220 | H11: 213.28 | I11: FS | K11: =_xlfn.XLOOKUP(Table4[[#This Row],[ProductID_Clean]],Table3[ProductID],Table3[BU],"Missing Value",0) -> Field Services | M11: P-SA-003 | N11: =_xlfn.XLOOKUP(Table15[[#This Row],[ProductID]],Table3[ProductID],Table3[StdVarCost_Clean]) -> 95 | O11: =_xlfn.XLOOKUP(Table15[[#This Row],[ProductID]],Table4[ProductID_Clean],Table4[ActualCost_Clean]) -> 93.7 | P11: =Table15[[#This Row],[Standard Variable Cost]]-Table15[[#This Row],[Actual Variable Cost]] -> 1.3 | Q11: =Table15[[#This Row],[Cost Variance vs Standard]]/Table15[[#This Row],[Standard Variable Cost]] -> 0.013684211
A12: COST-5217 | B12: 2025-06 | C12: P-FS-001 | D12: P-FS-001 | E12: Variable COGS | F12: Variable | G12: 980 | H12: 1118.05 | I12: FS | K12: =_xlfn.XLOOKUP(Table4[[#This Row],[ProductID_Clean]],Table3[ProductID],Table3[BU],"Missing Value",0) -> Field Services | M12: P-SA-004 | N12: =_xlfn.XLOOKUP(Table15[[#This Row],[ProductID]],Table3[ProductID],Table3[StdVarCost_Clean]) -> 65 | O12: =_xlfn.XLOOKUP(Table15[[#This Row],[ProductID]],Table4[ProductID_Clean],Table4[ActualCost_Clean]) -> 66.33 | P12: =Table15[[#This Row],[Standard Variable Cost]]-Table15[[#This Row],[Actual Variable Cost]] -> -1.33 | Q12: =Table15[[#This Row],[Cost Variance vs Standard]]/Table15[[#This Row],[Standard Variable Cost]] -> -0.020461538
A13: COST-5218 | B13: 2025-06 | C13: P-FS-001 | D13: P-FS-001 | E13: Fixed Allocation | F13: Fixed | G13: 220 | H13: 213.4 | I13: FS | K13: =_xlfn.XLOOKUP(Table4[[#This Row],[ProductID_Clean]],Table3[ProductID],Table3[BU],"Missing Value",0) -> Field Services | M13: P-SA-005 | N13: =_xlfn.XLOOKUP(Table15[[#This Row],[ProductID]],Table3[ProductID],Table3[StdVarCost_Clean]) -> 140 | O13: =_xlfn.XLOOKUP(Table15[[#This Row],[ProductID]],Table4[ProductID_Clean],Table4[ActualCost_Clean]) -> 253.97 | P13: =Table15[[#This Row],[Standard Variable Cost]]-Table15[[#This Row],[Actual Variable Cost]] -> -113.97 | Q13: =Table15[[#This Row],[Cost Variance vs Standard]]/Table15[[#This Row],[Standard Variable Cost]] -> -0.81407143
A14: COST-5029 | B14: 2025-01 | C14: P-FS-002 | D14: P-FS-002 | E14: Variable COGS | F14: Variable | G14: 1120 | H14: 1263.71 | I14: FS | K14: =_xlfn.XLOOKUP(Table4[[#This Row],[ProductID_Clean]],Table3[ProductID],Table3[BU],"Missing Value",0) -> Field Services | M14: P-SI-001 | N14: =_xlfn.XLOOKUP(Table15[[#This Row],[ProductID]],Table3[ProductID],Table3[StdVarCost_Clean]) -> 187.5 | O14: =_xlfn.XLOOKUP(Table15[[#This Row],[ProductID]],Table4[ProductID_Clean],Table4[ActualCost_Clean]) -> 185.89 | P14: =Table15[[#This Row],[Standard Variable Cost]]-Table15[[#This Row],[Actual Variable Cost]] -> 1.61 | Q14: =Table15[[#This Row],[Cost Variance vs Standard]]/Table15[[#This Row],[Standard Variable Cost]] -> 0.0085866667
... A21: COST-5144 | B21: 2025-04 | C21: P-FS-002 | D21: P-FS-002 | E21: Fixed Allocation | F21: Fixed | G21: 280 | H21: 290.36 | I21: FS | K21: =_xlfn.XLOOKUP(Table4[[#This Row],[ProductID_Clean]],Table3[ProductID],Table3[BU],"Missing Value",0) -> Field Services | M21: P-SI-008 | N21: =_xlfn.XLOOKUP(Table15[[#This Row],[ProductID]],Table3[ProductID],Table3[StdVarCost_Clean]) -> 385 | O21: =_xlfn.XLOOKUP(Table15[[#This Row],[ProductID]],Table4[ProductID_Clean],Table4[ActualCost_Clean]) -> 386.6 | P21: =Table15[[#This Row],[Standard Variable Cost]]-Table15[[#This Row],[Actual Variable Cost]] -> -1.6 | Q21: =Table15[[#This Row],[Cost Variance vs Standard]]/Table15[[#This Row],[Standard Variable Cost]] -> -0.0041558442
A22: COST-5181 | B22: 2025-05 | C22: P-FS-002 | D22: P-FS-002 | E22: Variable COGS | F22: Variable | G22: 1120 | H22: 1247.2 | I22: FS | K22: =_xlfn.XLOOKUP(Table4[[#This Row],[ProductID_Clean]],Table3[ProductID],Table3[BU],"Missing Value",0) -> Field Services
A23: COST-5182 | B23: 2025-05 | C23: P-FS-002 | D23: P-FS-002 | E23: fixed allocation | F23: Fixed | G23: 280 | H23: 283.91 | I23: FS | K23: =_xlfn.XLOOKUP(Table4[[#This Row],[ProductID_Clean]],Table3[ProductID],Table3[BU],"Missing Value",0) -> Field Services | M23: Negative = Unfavorable / Overrun; Positive = Favorable / Saving
A24: COST-5219 | B24: 2025-06 | C24: P-FS-002 | D24: P-FS-002 | E24: Variable COGS | F24: Variable | G24: 1120 | H24: 1271.29 | I24: FS | K24: =_xlfn.XLOOKUP(Table4[[#This Row],[ProductID_Clean]],Table3[ProductID],Table3[BU],"Missing Value",0) -> Field Services | M24: Note: P-SA-005 excluded from the cost-overrun ranking because January 2025 Variable COGS is missing. Complete monthly Actual Variable Cost data is required for a full H1 comparison.
A25: COST-5220 | B25: 2025-06 | C25: P-FS-002 | D25: P-FS-002 | E25: Fixed Allocation | F25: Fixed | G25: 280 | H25: 296.85 | I25: FS | K25: =_xlfn.XLOOKUP(Table4[[#This Row],[ProductID_Clean]],Table3[ProductID],Table3[BU],"Missing Value",0) -> Field Services
A26: COST-5031 | B26: 2025-01 | C26: P-FS-003 | D26: P-FS-003 | E26: Variable COGS | F26: Variable | G26: 1850 | H26: 2111.06 | I26: FS | K26: =_xlfn.XLOOKUP(Table4[[#This Row],[ProductID_Clean]],Table3[ProductID],Table3[BU],"Missing Value",0) -> Field Services
A27: COST-5032 | B27: 2025-01 | C27: P-FS-003 | D27: P-FS-003 | E27: Fixed Allocation | F27: Fixed | G27: 410 | H27: 424.87 | I27: FS | K27: =_xlfn.XLOOKUP(Table4[[#This Row],[ProductID_Clean]],Table3[ProductID],Table3[BU],"Missing Value",0) -> Field Services
A28: COST-5070 | B28: 2025-02 | C28: P-FS-003 | D28: P-FS-003 | E28: Fixed Allocation | F28: Fixed | G28: 410 | H28: 415.32 | I28: FS | K28: =_xlfn.XLOOKUP(Table4[[#This Row],[ProductID_Clean]],Table3[ProductID],Table3[BU],"Missing Value",0) -> Field Services
A29: COST-5069 | B29: 2025-02 | C29: P-FS-003 | D29: P-FS-003 | E29: Variable COGS | F29: Variable | G29: 1850 | H29: 2067.25 | I29: FS | K29: =_xlfn.XLOOKUP(Table4[[#This Row],[ProductID_Clean]],Table3[ProductID],Table3[BU],"Missing Value",0) -> Field Services | M29: Cost Category | N29: Actual Cost | O29: % of Total Overhead
A30: COST-5107 | B30: 2025-03 | C30: P-FS-003 | D30: P-FS-003 | E30: Variable COGS | F30: Variable | G30: 1850 | H30: 2105 | I30: FS | K30: =_xlfn.XLOOKUP(Table4[[#This Row],[ProductID_Clean]],Table3[ProductID],Table3[BU],"Missing Value",0) -> Field Services | M30: Regional Sales Overhead | N30: =SUMIF(Table4[CostCategory],Table18[[#This Row],[Cost Category]],Table4[ActualCost_Clean]) -> 884457.01 | O30: =Table18[[#This Row],[Actual Cost]]/Table18[[#Totals],[Actual Cost]] -> 0.37458513
A31: COST-5108 | B31: 2025-03 | C31: P-FS-003 | D31: P-FS-003 | E31: Fixed Allocation | F31: Fixed | G31: 410 | H31: 408.18 | I31: FS | K31: =_xlfn.XLOOKUP(Table4[[#This Row],[ProductID_Clean]],Table3[ProductID],Table3[BU],"Missing Value",0) -> Field Services | M31: Shared R&D Allocation | N31: =SUMIF(Table4[CostCategory],Table18[[#This Row],[Cost Category]],Table4[ActualCost_Clean]) -> 619088.43 | O31: =Table18[[#This Row],[Actual Cost]]/Table18[[#Totals],[Actual Cost]] -> 0.26219626
A32: COST-5145 | B32: 2025-04 | C32: P-FS-003 | D32: P-FS-003 | E32: Variable COGS | F32: Variable | G32: 1850 | H32: 2112.37 | I32: FS | K32: =_xlfn.XLOOKUP(Table4[[#This Row],[ProductID_Clean]],Table3[ProductID],Table3[BU],"Missing Value",0) -> Field Services | M32: Logistics & Distribution | N32: =SUMIF(Table4[CostCategory],Table18[[#This Row],[Cost Category]],Table4[ActualCost_Clean]) -> 466498.32 | O32: =Table18[[#This Row],[Actual Cost]]/Table18[[#Totals],[Actual Cost]] -> 0.19757131
A33: COST-5146 | B33: 2025-04 | C33: P-FS-003 | D33: P-FS-003 | E33: Fixed Allocation | F33: Fixed | G33: 410 | H33: 434.23 | I33: FS | K33: =_xlfn.XLOOKUP(Table4[[#This Row],[ProductID_Clean]],Table3[ProductID],Table3[BU],"Missing Value",0) -> Field Services | M33: Quality Assurance | N33: =SUMIF(Table4[CostCategory],Table18[[#This Row],[Cost Category]],Table4[ActualCost_Clean]) -> 296005.53 | O33: =Table18[[#This Row],[Actual Cost]]/Table18[[#Totals],[Actual Cost]] -> 0.12536423
A34: COST-5183 | B34: 2025-05 | C34: P-FS-003 | D34: P-FS-003 | E34: Variable COGS | F34: Variable | G34: 1850 | H34: 2122.36 | I34: FS | K34: =_xlfn.XLOOKUP(Table4[[#This Row],[ProductID_Clean]],Table3[ProductID],Table3[BU],"Missing Value",0) -> Field Services | M34: Variable COGS | N34: =SUMIF(Table4[CostCategory],Table18[[#This Row],[Cost Category]],Table4[ActualCost_Clean]) -> 72363.06 | O34: =Table18[[#This Row],[Actual Cost]]/Table18[[#Totals],[Actual Cost]] -> 0.030647194
A35: COST-5184 | B35: 2025-05 | C35: P-FS-003 | D35: P-FS-003 | E35: Fixed Allocation | F35: Fixed | G35: 410 | H35: 393.61 | I35: FS | K35: =_xlfn.XLOOKUP(Table4[[#This Row],[ProductID_Clean]],Table3[ProductID],Table3[BU],"Missing Value",0) -> Field Services | M35: Fixed Allocation | N35: =SUMIF(Table4[CostCategory],Table18[[#This Row],[Cost Category]],Table4[ActualCost_Clean]) -> 22751.9 | O35: =Table18[[#This Row],[Actual Cost]]/Table18[[#Totals],[Actual Cost]] -> 0.009635882
A36: COST-5221 | B36: 2025-06 | C36: P-FS-003 | D36: P-FS-003 | E36: Variable COGS | F36: Variable | G36: 1850 | H36: 2152.22 | I36: FS | K36: =_xlfn.XLOOKUP(Table4[[#This Row],[ProductID_Clean]],Table3[ProductID],Table3[BU],"Missing Value",0) -> Field Services | M36: Total | N36: =SUBTOTAL(109,Table18[Actual Cost]) -> 2361164.2 | O36: =SUBTOTAL(109,Table18[% of Total Overhead]) -> 1
A37: COST-5222 | B37: 2025-06 | C37: P-FS-003 | D37: P-FS-003 | E37: Fixed Allocation | F37: Fixed | G37: 410 | H37: 393.65 | I37: FS | K37: =_xlfn.XLOOKUP(Table4[[#This Row],[ProductID_Clean]],Table3[ProductID],Table3[BU],"Missing Value",0) -> Field Services
A38: COST-5033 | B38: 2025-01 | C38: P-FS-004 | D38: P-FS-004 | E38: Variable COGS | F38: Variable | G38: 1650 | H38: 2021.96 | I38: FS | K38: =_xlfn.XLOOKUP(Table4[[#This Row],[ProductID_Clean]],Table3[ProductID],Table3[BU],"Missing Value",0) -> Field Services | M38: Notes | N38: Actual Overhead Cost | O38: % of Total Overhead
A39: COST-5034 | B39: 2025-01 | C39: P-FS-004 | D39: P-FS-004 | E39: Fixed Allocation | F39: Fixed | G39: 350 | H39: 369.2 | I39: FS | K39: =_xlfn.XLOOKUP(Table4[[#This Row],[ProductID_Clean]],Table3[ProductID],Table3[BU],"Missing Value",0) -> Field Services | M39: Blank | N39: 95114.96 | O39: =Table19[[#This Row],[Actual Overhead Cost]]/Table19[[#Totals],[Actual Overhead Cost]] -> 0.040283076
A40: COST-5071 | B40: 2025-02 | C40: P-FS-004 | D40: P-FS-004 | E40: Variable COGS | F40: Variable | G40: 1650 | H40: 2067.88 | I40: FS | K40: =_xlfn.XLOOKUP(Table4[[#This Row],[ProductID_Clean]],Table3[ProductID],Table3[BU],"Missing Value",0) -> Field Services | M40: North America overhead | N40: =SUMIF(Table4[Notes],Table19[[#This Row],[Notes]],Table4[ActualCost_Clean]) -> 818074.55 | O40: =Table19[[#This Row],[Actual Overhead Cost]]/Table19[[#Totals],[Actual Overhead Cost]] -> 0.34647084
A41: COST-5072 | B41: 2025-02 | C41: P-FS-004 | D41: P-FS-004 | E41: Fixed Allocation | F41: Fixed | G41: 350 | H41: 341.28 | I41: FS | K41: =_xlfn.XLOOKUP(Table4[[#This Row],[ProductID_Clean]],Table3[ProductID],Table3[BU],"Missing Value",0) -> Field Services | M41: EMEA overhead | N41: =SUMIF(Table4[Notes],Table19[[#This Row],[Notes]],Table4[ActualCost_Clean]) -> 589408.46 | O41: =Table19[[#This Row],[Actual Overhead Cost]]/Table19[[#Totals],[Actual Overhead Cost]] -> 0.2496262
A42: COST-5109 | B42: 2025-03 | C42: P-FS-004 | D42: P-FS-004 | E42: Variable COGS | F42: Variable | G42: 1650 | H42: 2041.18 | I42: FS | K42: =_xlfn.XLOOKUP(Table4[[#This Row],[ProductID_Clean]],Table3[ProductID],Table3[BU],"Missing Value",0) -> Field Services | M42: APAC overhead | N42: =SUMIF(Table4[Notes],Table19[[#This Row],[Notes]],Table4[ActualCost_Clean]) -> 523502.7 | O42: =Table19[[#This Row],[Actual Overhead Cost]]/Table19[[#Totals],[Actual Overhead Cost]] -> 0.2217138
A43: COST-5110 | B43: 2025-03 | C43: P-FS-004 | D43: P-FS-004 | E43: Fixed Allocation | F43: Fixed | G43: 350 | H43: 338.29 | I43: FS | K43: =_xlfn.XLOOKUP(Table4[[#This Row],[ProductID_Clean]],Table3[ProductID],Table3[BU],"Missing Value",0) -> Field Services | M43: Latin America overhead | N43: =SUMIF(Table4[Notes],Table19[[#This Row],[Notes]],Table4[ActualCost_Clean]) -> 335063.58 | O43: =Table19[[#This Row],[Actual Overhead Cost]]/Table19[[#Totals],[Actual Overhead Cost]] -> 0.14190609
A44: COST-5147 | B44: 2025-04 | C44: P-FS-004 | D44: P-FS-004 | E44: Variable COGS | F44: Variable | G44: 1650 | H44: 2023.48 | I44: FS | K44: =_xlfn.XLOOKUP(Table4[[#This Row],[ProductID_Clean]],Table3[ProductID],Table3[BU],"Missing Value",0) -> Field Services | M44: Total | N44: =SUBTOTAL(109,Table19[Actual Overhead Cost]) -> 2361164.2 | O44: =SUBTOTAL(109,Table19[% of Total Overhead]) -> 1
A45: COST-5148 | B45: 2025-04 | C45: P-FS-004 | D45: P-FS-004 | E45: Fixed Allocation | F45: Fixed | G45: 350 | H45: 350.82 | I45: FS | K45: =_xlfn.XLOOKUP(Table4[[#This Row],[ProductID_Clean]],Table3[ProductID],Table3[BU],"Missing Value",0) -> Field Services
A46: COST-5185 | B46: 2025-05 | C46: P-FS-004 | D46: P-FS-004 | E46: Variable COGS | F46: Variable | G46: 1650 | H46: 2070.92 | I46: FS | K46: =_xlfn.XLOOKUP(Table4[[#This Row],[ProductID_Clean]],Table3[ProductID],Table3[BU],"Missing Value",0) -> Field Services
...

Sheet Budget
A1: BudgetID | B1: Period | C1: BusinessUnit | D1: BusinessUnit_clean | E1: Region_Clean | F1: RevenueBudget | G1: VariableCostBudget | H1: FixedCostBudget | I1: ContributionProfitTarget | J1: OperatingProfitTarget | K1: Version
A2: BUD-2025-01-SI-NA | B2: 2025-01 | C2: Sensors & Instruments | D2: =SUBSTITUTE(SUBSTITUTE(TRIM(Table5[[#This Row],[BusinessUnit]]),"Software and Analytics","Software & Analytics"),"Sensors and Instruments","Sensors & Instruments") -> Sensors & Instruments | E2: N. AMERICA | F2: 359017 | G2: 140163 | H2: 41528 | I2: 218854 | J2: 177326 | K2: Board Approved H1 2025
A3: BUD-2025-01-SI-EM | B3: 2025-01 | C3: Sensors & Instruments | D3: =SUBSTITUTE(SUBSTITUTE(TRIM(Table5[[#This Row],[BusinessUnit]]),"Software and Analytics","Software & Analytics"),"Sensors and Instruments","Sensors & Instruments") -> Sensors & Instruments | E3: EMEA | F3: 248509 | G3: 99942 | H3: 28770 | I3: 148567 | J3: 119797 | K3: Board Approved H1 2025
A4: BUD-2025-01-SI-AP | B4: 2025-01 | C4: Sensors & Instruments | D4: =SUBSTITUTE(SUBSTITUTE(TRIM(Table5[[#This Row],[BusinessUnit]]),"Software and Analytics","Software & Analytics"),"Sensors and Instruments","Sensors & Instruments") -> Sensors & Instruments | E4: APAC | F4: 165364 | G4: 65135 | H4: 19988 | I4: 100229 | J4: 80241 | K4: Board Approved H1 2025
A5: BUD-2025-01-SI-LA | B5: 2025-01 | C5: Sensors & Instruments | D5: =SUBSTITUTE(SUBSTITUTE(TRIM(Table5[[#This Row],[BusinessUnit]]),"Software and Analytics","Software & Analytics"),"Sensors and Instruments","Sensors & Instruments") -> Sensors & Instruments | E5: LATIN AMERICA | F5: 72840 | G5: 29238 | H5: 8670 | I5: 43602 | J5: 34932 | K5: Board Approved H1 2025
A6: BUD-2025-01-SA-NA | B6: 2025-01 | C6: Software & Analytics | D6: =SUBSTITUTE(SUBSTITUTE(TRIM(Table5[[#This Row],[BusinessUnit]]),"Software and Analytics","Software & Analytics"),"Sensors and Instruments","Sensors & Instruments") -> Software & Analytics | E6: N. AMERICA | F6: 265815 | G6: 14363 | H6: 46872 | I6: 251452 | J6: 204580 | K6: Board Approved H1 2025
A7: BUD-2025-01-SA-EM | B7: 2025-01 | C7: Software and Analytics | D7: =SUBSTITUTE(SUBSTITUTE(TRIM(Table5[[#This Row],[BusinessUnit]]),"Software and Analytics","Software & Analytics"),"Sensors and Instruments","Sensors & Instruments") -> Software & Analytics | E7: EMEA | F7: 165690 | G7: 9017 | H7: 28485 | I7: 156673 | J7: 128188 | K7: Board Approved H1 2025
A8: BUD-2025-01-SA-AP | B8: 2025-01 | C8: Software & Analytics | D8: =SUBSTITUTE(SUBSTITUTE(TRIM(Table5[[#This Row],[BusinessUnit]]),"Software and Analytics","Software & Analytics"),"Sensors and Instruments","Sensors & Instruments") -> Software & Analytics | E8: APAC | F8: 100757 | G8: 5563 | H8: 18067 | I8: 95194 | J8: 77127 | K8: Board Approved H1 2025
A9: BUD-2025-01-SA-LA | B9: 2025-01 | C9: Software & Analytics | D9: =SUBSTITUTE(SUBSTITUTE(TRIM(Table5[[#This Row],[BusinessUnit]]),"Software and Analytics","Software & Analytics"),"Sensors and Instruments","Sensors & Instruments") -> Software & Analytics | E9: LATIN AMERICA | F9: 39651 | G9: 2223 | H9: 7049 | I9: 37428 | J9: 30379 | K9: Board Approved H1 2025
